------ MEMORY MANAGEMENT TEST 0 ------------------------------------
./mem input/proc/m0
000: 00000-003ff - PID: 01 (idx 000, nxt: -01)
	003e8: 15
001: 00400-007ff - PID: 01 (idx 000, nxt: 002)
002: 00800-00bff - PID: 01 (idx 001, nxt: 003)
003: 00c00-00fff - PID: 01 (idx 002, nxt: 004)
004: 01000-013ff - PID: 01 (idx 003, nxt: -01)
013: 03400-037ff - PID: 01 (idx 000, nxt: -01)
	03414: 66
NOTE: Read file output/m0 to verify your result
------ MEMORY MANAGEMENT TEST 1 ------------------------------------
./mem input/proc/m1
NOTE: Read file output/m1 to verify your result (your implementation should print nothing)
------ SCHEDULING TEST 0 -------------------------------------------
./os sched_0
Time slot   0
	Loaded a process at input/proc/s0, PID: 1 PRIO: 0
Time slot   1
	CPU 0: Dispatched process  1
Time slot   2
Time slot   3
	CPU 0: Put process  1 to run queue
	CPU 0: Dispatched process  1
	Loaded a process at input/proc/s1, PID: 2 PRIO: 1
Time slot   4
Time slot   5
	CPU 0: Put process  1 to run queue
	CPU 0: Dispatched process  2
Time slot   6
Time slot   7
	CPU 0: Put process  2 to run queue
	CPU 0: Dispatched process  2
Time slot   8
Time slot   9
	CPU 0: Put process  2 to run queue
	CPU 0: Dispatched process  2
Time slot  10
Time slot  11
	CPU 0: Put process  2 to run queue
	CPU 0: Dispatched process  2
Time slot  12
	CPU 0: Processed  2 has finished
	CPU 0: Dispatched process  1
Time slot  13
Time slot  14
	CPU 0: Put process  1 to run queue
	CPU 0: Dispatched process  1
Time slot  15
Time slot  16
	CPU 0: Put process  1 to run queue
	CPU 0: Dispatched process  1
Time slot  17
Time slot  18
	CPU 0: Put process  1 to run queue
	CPU 0: Dispatched process  1
Time slot  19
Time slot  20
	CPU 0: Put process  1 to run queue
	CPU 0: Dispatched process  1
Time slot  21
Time slot  22
	CPU 0: Put process  1 to run queue
	CPU 0: Dispatched process  1
Time slot  23
	CPU 0: Processed  1 has finished
	CPU 0 stopped
NOTE: Read file output/sched_0 to verify your result
------ SCHEDULING TEST 1 -------------------------------------------
./os sched_1
Time slot   0
	Loaded a process at input/proc/s0, PID: 1 PRIO: 0
Time slot   1
	CPU 0: Dispatched process  1
Time slot   2
Time slot   3
	CPU 0: Put process  1 to run queue
	CPU 0: Dispatched process  1
	Loaded a process at input/proc/s1, PID: 2 PRIO: 1
Time slot   4
Time slot   5
	CPU 0: Put process  1 to run queue
	CPU 0: Dispatched process  2
	Loaded a process at input/proc/s2, PID: 3 PRIO: 2
Time slot   6
Time slot   7
	CPU 0: Put process  2 to run queue
	CPU 0: Dispatched process  3
	Loaded a process at input/proc/s3, PID: 4 PRIO: 3
Time slot   8
Time slot   9
	CPU 0: Put process  3 to run queue
	CPU 0: Dispatched process  4
Time slot  10
Time slot  11
	CPU 0: Put process  4 to run queue
	CPU 0: Dispatched process  4
Time slot  12
Time slot  13
	CPU 0: Put process  4 to run queue
	CPU 0: Dispatched process  4
Time slot  14
Time slot  15
	CPU 0: Put process  4 to run queue
	CPU 0: Dispatched process  4
Time slot  16
Time slot  17
	CPU 0: Put process  4 to run queue
	CPU 0: Dispatched process  4
Time slot  18
Time slot  19
	CPU 0: Put process  4 to run queue
	CPU 0: Dispatched process  4
Time slot  20
	CPU 0: Processed  4 has finished
	CPU 0: Dispatched process  3
Time slot  21
Time slot  22
	CPU 0: Put process  3 to run queue
	CPU 0: Dispatched process  3
Time slot  23
Time slot  24
	CPU 0: Put process  3 to run queue
	CPU 0: Dispatched process  3
Time slot  25
Time slot  26
	CPU 0: Put process  3 to run queue
	CPU 0: Dispatched process  3
Time slot  27
Time slot  28
	CPU 0: Put process  3 to run queue
	CPU 0: Dispatched process  3
Time slot  29
Time slot  30
	CPU 0: Processed  3 has finished
	CPU 0: Dispatched process  2
Time slot  31
Time slot  32
	CPU 0: Put process  2 to run queue
	CPU 0: Dispatched process  2
Time slot  33
Time slot  34
	CPU 0: Put process  2 to run queue
	CPU 0: Dispatched process  2
Time slot  35
	CPU 0: Processed  2 has finished
	CPU 0: Dispatched process  1
Time slot  36
Time slot  37
	CPU 0: Put process  1 to run queue
	CPU 0: Dispatched process  1
Time slot  38
Time slot  39
	CPU 0: Put process  1 to run queue
	CPU 0: Dispatched process  1
Time slot  40
Time slot  41
	CPU 0: Put process  1 to run queue
	CPU 0: Dispatched process  1
Time slot  42
Time slot  43
	CPU 0: Put process  1 to run queue
	CPU 0: Dispatched process  1
Time slot  44
Time slot  45
	CPU 0: Put process  1 to run queue
	CPU 0: Dispatched process  1
Time slot  46
	CPU 0: Processed  1 has finished
	CPU 0 stopped
NOTE: Read file output/sched_1 to verify your result
----- OS TEST 0 ----------------------------------------------------
./os os_mlq_0
Time slot   0
	Loaded a process at input/proc/p0, PID: 1 PRIO: 0
Time slot   1
	CPU 1: Dispatched process  1
Time slot   2
	Loaded a process at input/proc/p1, PID: 2 PRIO: 15
	CPU 0: Dispatched process  2
Time slot   3
	Loaded a process at input/proc/p1, PID: 3 PRIO: 0
Time slot   4
	Loaded a process at input/proc/p1, PID: 4 PRIO: 0
Time slot   5
Time slot   6
Time slot   7
	CPU 1: Put process  1 to run queue
	CPU 1: Dispatched process  3
Time slot   8
	CPU 0: Put process  2 to run queue
	CPU 0: Dispatched process  2
Time slot   9
Time slot  10
Time slot  11
Time slot  12
	CPU 0: Processed  2 has finished
	CPU 0: Dispatched process  4
	CPU 1: Put process  3 to run queue
	CPU 1: Dispatched process  1
Time slot  13
Time slot  14
Time slot  15
Time slot  16
	CPU 1: Processed  1 has finished
	CPU 1: Dispatched process  3
Time slot  17
Time slot  18
	CPU 0: Put process  4 to run queue
	CPU 0: Dispatched process  4
Time slot  19
Time slot  20
	CPU 1: Processed  3 has finished
	CPU 1 stopped
Time slot  21
Time slot  22
	CPU 0: Processed  4 has finished
	CPU 0 stopped
NOTE: Read file output/os_mlq_0 to verify your result
----- OS TEST 1 ----------------------------------------------------
./os os_mlq_1
Time slot   0
	Loaded a process at input/proc/p0, PID: 1 PRIO: 139
	CPU 3: Dispatched process  1
Time slot   1
Time slot   2
	Loaded a process at input/proc/s3, PID: 2 PRIO: 39
	CPU 3: Put process  1 to run queue
Time slot   3
	CPU 2: Dispatched process  2
	CPU 3: Dispatched process  1
	Loaded a process at input/proc/m1, PID: 3 PRIO: 15
Time slot   4
	CPU 1: Dispatched process  3
	CPU 3: Put process  1 to run queue
	CPU 3: Dispatched process  1
	CPU 2: Put process  2 to run queue
	CPU 2: Dispatched process  2
Time slot   5
	Loaded a process at input/proc/s2, PID: 4 PRIO: 120
Time slot   6
	CPU 1: Put process  3 to run queue
	CPU 0: Dispatched process  4
	CPU 1: Dispatched process  3
	CPU 2: Put process  2 to run queue
Time slot   7
	CPU 2: Dispatched process  2
	CPU 3: Put process  1 to run queue
	CPU 3: Dispatched process  1
	Loaded a process at input/proc/m0, PID: 5 PRIO: 120
Time slot   8
	CPU 1: Put process  3 to run queue
	CPU 0: Put process  4 to run queue
	CPU 1: Dispatched process  5
	CPU 0: Dispatched process  4
	Loaded a process at input/proc/p1, PID: 6 PRIO: 15
	CPU 3: Put process  1 to run queue
	CPU 3: Dispatched process  1
	CPU 2: Put process  2 to run queue
	CPU 2: Dispatched process  2
Time slot   9
Time slot  10
	CPU 1: Put process  5 to run queue
	CPU 1: Dispatched process  5
	CPU 0: Put process  4 to run queue
	CPU 0: Dispatched process  4
	Loaded a process at input/proc/s0, PID: 7 PRIO: 38
	CPU 3: Processed  1 has finished
	CPU 2: Put process  2 to run queue
Time slot  11
	CPU 3: Dispatched process  7
	CPU 2: Dispatched process  2
	CPU 1: Put process  5 to run queue
	CPU 1: Dispatched process  5
Time slot  12
	CPU 0: Put process  4 to run queue
	CPU 0: Dispatched process  4
	CPU 3: Put process  7 to run queue
	CPU 3: Dispatched process  7
	CPU 2: Put process  2 to run queue
	CPU 2: Dispatched process  2
Time slot  13
	CPU 2: Processed  2 has finished
Time slot  14
	CPU 1: Put process  5 to run queue
	CPU 1: Dispatched process  5
	CPU 2: Dispatched process  3
	CPU 0: Put process  4 to run queue
	CPU 0: Dispatched process  4
	CPU 3: Put process  7 to run queue
	CPU 3: Dispatched process  7
Time slot  15
	CPU 1: Processed  5 has finished
	CPU 1: Dispatched process  6
	Loaded a process at input/proc/s1, PID: 8 PRIO: 0
	CPU 2: Put process  3 to run queue
	CPU 2: Dispatched process  3
Time slot  16
	CPU 0: Put process  4 to run queue
	CPU 0: Dispatched process  4
	CPU 3: Put process  7 to run queue
	CPU 3: Dispatched process  7
	CPU 1: Put process  6 to run queue
	CPU 1: Dispatched process  6
Time slot  17
	CPU 2: Processed  3 has finished
	CPU 2: Dispatched process  8
Time slot  18
	CPU 0: Processed  4 has finished
	CPU 0 stopped
	CPU 3: Put process  7 to run queue
	CPU 3: Dispatched process  7
Time slot  19
	CPU 1: Put process  6 to run queue
	CPU 1: Dispatched process  6
	CPU 2: Put process  8 to run queue
	CPU 2: Dispatched process  8
Time slot  20
Time slot  21
	CPU 3: Put process  7 to run queue
	CPU 3: Dispatched process  7
	CPU 1: Put process  6 to run queue
	CPU 1: Dispatched process  6
	CPU 2: Put process  8 to run queue
	CPU 2: Dispatched process  8
Time slot  22
Time slot  23
	CPU 3: Put process  7 to run queue
	CPU 1: Put process  6 to run queue
	CPU 3: Dispatched process  7
	CPU 1: Dispatched process  6
	CPU 2: Put process  8 to run queue
Time slot  24
	CPU 2: Dispatched process  8
	CPU 2: Processed  8 has finished
	CPU 2 stopped
Time slot  25
	CPU 3: Put process  7 to run queue
	CPU 1: Processed  6 has finished
	CPU 3: Dispatched process  7
	CPU 1 stopped
Time slot  26
	CPU 3: Processed  7 has finished
	CPU 3 stopped
NOTE: Read file output/os_mlq_1 to verify your result
----- OS TEST 2 ----------------------------------------------------
./os os_mlq_2
Time slot   0
	Loaded a process at input/proc/s4, PID: 1 PRIO: 4
Time slot   1
	CPU 1: Dispatched process  1
Time slot   2
	Loaded a process at input/proc/s3, PID: 2 PRIO: 3
Time slot   3
	CPU 1: Put process  1 to run queue
	CPU 1: Dispatched process  1
	CPU 0: Dispatched process  2
Time slot   4
	Loaded a process at input/proc/m1, PID: 3 PRIO: 2
Time slot   5
	CPU 0: Put process  2 to run queue
	CPU 0: Dispatched process  2
	CPU 1: Put process  1 to run queue
	CPU 1: Dispatched process  1
Time slot   6
	Loaded a process at input/proc/s2, PID: 4 PRIO: 3
Time slot   7
	CPU 1: Put process  1 to run queue
	CPU 1: Dispatched process  1
	CPU 0: Put process  2 to run queue
	CPU 0: Dispatched process  4
	Loaded a process at input/proc/m0, PID: 5 PRIO: 3
Time slot   8
	CPU 1: Processed  1 has finished
	CPU 1: Dispatched process  2
	Loaded a process at input/proc/p1, PID: 6 PRIO: 2
Time slot   9
	CPU 0: Put process  4 to run queue
	CPU 0: Dispatched process  5
Time slot  10
	CPU 1: Put process  2 to run queue
	CPU 1: Dispatched process  4
Time slot  11
	Loaded a process at input/proc/s0, PID: 7 PRIO: 1
	CPU 0: Put process  5 to run queue
	CPU 0: Dispatched process  2
Time slot  12
	CPU 1: Put process  4 to run queue
	CPU 1: Dispatched process  5
Time slot  13
	CPU 0: Put process  2 to run queue
	CPU 0: Dispatched process  4
Time slot  14
	CPU 1: Put process  5 to run queue
	CPU 1: Dispatched process  2
Time slot  15
	CPU 0: Put process  4 to run queue
	CPU 0: Dispatched process  5
	CPU 1: Put process  2 to run queue
Time slot  16
	CPU 1: Dispatched process  4
	Loaded a process at input/proc/s1, PID: 8 PRIO: 0
Time slot  17
	CPU 0: Put process  5 to run queue
	CPU 0: Dispatched process  2
	CPU 1: Put process  4 to run queue
Time slot  18
	CPU 1: Dispatched process  5
	CPU 0: Processed  2 has finished
	CPU 0: Dispatched process  4
	CPU 1: Processed  5 has finished
Time slot  19
	CPU 1: Dispatched process  3
Time slot  20
	CPU 0: Put process  4 to run queue
	CPU 0: Dispatched process  4
Time slot  21
	CPU 1: Put process  3 to run queue
	CPU 1: Dispatched process  6
Time slot  22
	CPU 0: Processed  4 has finished
	CPU 0: Dispatched process  3
Time slot  23
	CPU 1: Put process  6 to run queue
	CPU 1: Dispatched process  6
Time slot  24
	CPU 0: Put process  3 to run queue
	CPU 0: Dispatched process  3
Time slot  25
	CPU 1: Put process  6 to run queue
	CPU 1: Dispatched process  6
Time slot  26
	CPU 0: Put process  3 to run queue
	CPU 0: Dispatched process  3
	CPU 1: Put process  6 to run queue
	CPU 1: Dispatched process  6
Time slot  27
Time slot  28
	CPU 0: Processed  3 has finished
	CPU 0: Dispatched process  7
	CPU 1: Put process  6 to run queue
	CPU 1: Dispatched process  6
Time slot  29
Time slot  30
	CPU 0: Put process  7 to run queue
	CPU 0: Dispatched process  7
	CPU 1: Processed  6 has finished
	CPU 1: Dispatched process  8
Time slot  31
Time slot  32
	CPU 0: Put process  7 to run queue
	CPU 0: Dispatched process  7
	CPU 1: Put process  8 to run queue
	CPU 1: Dispatched process  8
Time slot  33
Time slot  34
	CPU 0: Put process  7 to run queue
	CPU 0: Dispatched process  7
	CPU 1: Put process  8 to run queue
	CPU 1: Dispatched process  8
Time slot  35
Time slot  36
	CPU 0: Put process  7 to run queue
	CPU 0: Dispatched process  7
	CPU 1: Put process  8 to run queue
	CPU 1: Dispatched process  8
Time slot  37
	CPU 1: Processed  8 has finished
	CPU 1 stopped
Time slot  38
	CPU 0: Put process  7 to run queue
	CPU 0: Dispatched process  7
Time slot  39
Time slot  40
	CPU 0: Put process  7 to run queue
	CPU 0: Dispatched process  7
Time slot  41
Time slot  42
	CPU 0: Put process  7 to run queue
	CPU 0: Dispatched process  7
Time slot  43
	CPU 0: Processed  7 has finished
	CPU 0 stopped
NOTE: Read file output/os_mlq_2 to verify your result
